<?xml version="1.0"?>
<robot name="robot_nano_hand_teleop">


    <link name="base_link">
        <visual>
            <origin xyz="0 0 0" rpy="0 0 1.57"/>
            <geometry>
                <mesh filename="file:///home/wai/workspace/ros2_ws/src/robot_nano_hand_teleop/models/robot_nano_hand_base.stl" scale="1 1 1"/>
            </geometry>
        </visual>

    </link>


    <!-- Palm link -->
    <link name="palm_link">
        <visual>
            <origin xyz="0 0 0" rpy="0 0 1.57"/>
            <geometry>
                <mesh filename="file:///home/wai/workspace/ros2_ws/src/robot_nano_hand_teleop/models/robot_nano_hand_palm.stl" scale="1 1 1"/>
            </geometry>
           
        </visual>

    </link> 


    <!-- Palm joint -->
    <joint name="base_palm_joint" type="revolute">
        <origin xyz="0 0 0.132" rpy="0 0 0" />
        <parent link="base_link" />
        <child link="palm_link" />
        <axis xyz="0 1 0" />
        <limit effort="10" velocity="10" lower="0.0"  upper="1.57" />
    </joint>



    <!-- Finger1-->
    <link name="finger1_1_link">
        <visual>
            <origin xyz="0 0 0" rpy="0 0 1.57" />
            <geometry>
                <mesh filename="file:///home/wai/workspace/ros2_ws/src/robot_nano_hand_teleop/models/robot_nano_hand_finger1_link1.stl" scale="1 1 1"/>
            </geometry>   
        </visual>
    </link> 

    <joint name="palm_finger11_joint" type="revolute">
        <origin xyz="0.014588 -0.034298 0.105371" rpy="0.134887 0.077146 0.149703" />
        <parent link="palm_link" />
        <child link="finger1_1_link" />
        <limit effort="10" velocity="10" lower="0.0"  upper="1.57" />
    </joint>

    <link name="finger1_2_link">
        <visual>
            <origin xyz="0 0 0" rpy="0 0 1.57" />
            <geometry>
                <mesh filename="file:///home/wai/workspace/ros2_ws/src/robot_nano_hand_teleop/models/robot_nano_hand_finger1_link2.stl" scale="1 1 1"/>
            </geometry>
        </visual>

    </link> 

    <joint name="finger112_joint" type="revolute">
        <origin xyz="0 0 0.0026" rpy="0 0 0" />
        <parent link="finger1_1_link" />
        <child link="finger1_2_link" />
        <limit effort="10" velocity="10" lower="0.0"  upper="1.57" />
    </joint>


    <link name="finger1_3_link">
        <visual>
            <origin xyz="0 0 0" rpy="0 0 1.57" />
            <geometry>
                <mesh filename="file:///home/wai/workspace/ros2_ws/src/robot_nano_hand_teleop/models/robot_nano_hand_finger1_link3.stl" scale="1 1 1"/>
            </geometry>
        </visual>
    </link> 

    <joint name="finger123_joint" type="revolute">
        <origin xyz="0.00357 0.000126 0.040844" rpy="0 0 0" />
        <parent link="finger1_2_link" />
        <child link="finger1_3_link" />
        <limit effort="10" velocity="10" lower="0.0"  upper="1.57" />
    </joint>


    <!-- Finger1_4_link -->
    <link name="finger1_4_link">
        <visual>
            <origin xyz="0 0 0" rpy="0 0 1.57" />
            <geometry>
                <mesh filename="file:///home/wai/workspace/ros2_ws/src/robot_nano_hand_teleop/models/robot_nano_hand_finger1_link4.stl" scale="1 1 1"/>
            </geometry>
        </visual>

    </link> 


    <joint name="finger134_joint" type="revolute">
        <origin xyz="0.006306 0.000139 0.029247" rpy="0 0 0" />
        <parent link="finger1_3_link"/>
        <child link="finger1_4_link" />
        <limit effort="10" velocity="10" lower="0.0"  upper="1.57" />
    </joint>
   <!--/Finger1--> 




    <!-- Finger2-->
    <link name="finger2_1_link">
        <visual>
            <origin xyz="0 0 0" rpy="0 0 1.57" />
            <geometry>
                <mesh filename="file:///home/wai/workspace/ros2_ws/src/robot_nano_hand_teleop/models/robot_nano_hand_finger2_link1.stl" scale="1 1 1"/>
            </geometry>   
        </visual>
    </link> 

    <joint name="palm_finger21_joint" type="revolute">
        <origin xyz="0.007772 -0.013612 0.117984" rpy="0.062643 -0.000111 0.073654" />
        <parent link="palm_link" />
        <child link="finger2_1_link" />
        <limit effort="10" velocity="10" lower="0.0"  upper="1.57" />
    </joint>

    <link name="finger2_2_link">
        <visual>
            <origin xyz="0 0 0" rpy="0 0 1.57" />
            <geometry>
                <mesh filename="file:///home/wai/workspace/ros2_ws/src/robot_nano_hand_teleop/models/robot_nano_hand_finger2_link2.stl" scale="1 1 1"/>
            </geometry>
        </visual>

    </link> 

    <joint name="finger212_joint" type="revolute">
        <origin xyz="0 0 0.0026" rpy="0 0 0" />
        <parent link="finger2_1_link" />
        <child link="finger2_2_link" />
        <limit effort="10" velocity="10" lower="0.0"  upper="1.57" />
    </joint>


    <link name="finger2_3_link">
        <visual>
            <origin xyz="0 0 0" rpy="0 0 1.57" />
            <geometry>
                <mesh filename="file:///home/wai/workspace/ros2_ws/src/robot_nano_hand_teleop/models/robot_nano_hand_finger2_link3.stl" scale="1 1 1"/>
            </geometry>
        </visual>
    </link> 

    <joint name="finger223_joint" type="revolute">
        <origin xyz="-0.003183 0 0.045388" rpy="0 0 0" />
        <parent link="finger2_2_link" />
        <child link="finger2_3_link" />
        <limit effort="10" velocity="10" lower="0.0"  upper="1.57" />
    </joint>


    <!-- Finger1_4_link -->
    <link name="finger2_4_link">
        <visual>
            <origin xyz="0 0 0" rpy="0 0 1.57" />
            <geometry>
                <mesh filename="file:///home/wai/workspace/ros2_ws/src/robot_nano_hand_teleop/models/robot_nano_hand_finger2_link4.stl" scale="1 1 1"/>
            </geometry>
        </visual>

    </link> 


    <joint name="finger234_joint" type="revolute">
        <origin xyz="-0.002027 0 0.032436" rpy="0 0 0" />
        <parent link="finger2_3_link"/>
        <child link="finger2_4_link" />
        <limit effort="10" velocity="10" lower="0.0"  upper="1.57" />
    </joint>
   <!--/Finger2--> 


    <!-- Finger3-->
    <link name="finger3_1_link">
        <visual>
            <origin xyz="0 0 0" rpy="0 0 1.57" />
            <geometry>
                <mesh filename="file:///home/wai/workspace/ros2_ws/src/robot_nano_hand_teleop/models/robot_nano_hand_finger3_link1.stl" scale="1 1 1"/>
            </geometry>   
        </visual>
    </link> 

    <joint name="palm_finger31_joint" type="revolute">
        <origin xyz="0.00513 0.008315 0.123543" rpy="0 -0.014913 0" />
        <parent link="palm_link" />
        <child link="finger3_1_link" />
        <limit effort="10" velocity="10" lower="0.0"  upper="1.57" />
    </joint>

    <link name="finger3_2_link">
        <visual>
            <origin xyz="0 0 0" rpy="0 0 1.57" />
            <geometry>
                <mesh filename="file:///home/wai/workspace/ros2_ws/src/robot_nano_hand_teleop/models/robot_nano_hand_finger3_link2.stl" scale="1 1 1"/>
            </geometry>
        </visual>

    </link> 

    <joint name="finger312_joint" type="revolute">
        <origin xyz="0 0 0.0026" rpy="0 0 0" />
        <parent link="finger3_1_link" />
        <child link="finger3_2_link" />
        <limit effort="10" velocity="10" lower="0.0"  upper="1.57" />
    </joint>


    <link name="finger3_3_link">
        <visual>
            <origin xyz="0 0 0" rpy="0 0 1.57" />
            <geometry>
                <mesh filename="file:///home/wai/workspace/ros2_ws/src/robot_nano_hand_teleop/models/robot_nano_hand_finger3_link3.stl" scale="1 1 1"/>
            </geometry>
        </visual>
    </link> 

    <joint name="finger323_joint" type="revolute">
        <origin xyz="-0.003344 0 0.047682" rpy="0 0 0" />
        <parent link="finger3_2_link" />
        <child link="finger3_3_link" />
        <limit effort="10" velocity="10" lower="0.0"  upper="1.57" />
    </joint>

    <link name="finger3_4_link">
        <visual>
            <origin xyz="0 0 0" rpy="0 0 1.57" />
            <geometry>
                <mesh filename="file:///home/wai/workspace/ros2_ws/src/robot_nano_hand_teleop/models/robot_nano_hand_finger3_link4.stl" scale="1 1 1"/>
            </geometry>
        </visual>

    </link> 


    <joint name="finger334_joint" type="revolute">
        <origin xyz="-0.002127 0 0.034033" rpy="0 0 0" />
        <parent link="finger3_3_link"/>
        <child link="finger3_4_link" />
        <limit effort="10" velocity="10" lower="0.0"  upper="1.57" />
    </joint>
   <!--/Finger3-->


    <!-- Finger4-->
    <link name="finger4_1_link">
        <visual>
            <origin xyz="0 0 0" rpy="0 0 1.57" />
            <geometry>
                <mesh filename="file:///home/wai/workspace/ros2_ws/src/robot_nano_hand_teleop/models/robot_nano_hand_finger4_link1.stl" scale="1 1 1"/>
            </geometry>   
        </visual>
    </link> 

    <joint name="palm_finger41_joint" type="revolute">
        <origin xyz="0.00801 0.030342 0.117987" rpy="-0.085055 -0.001531 -0.102542" />
        <parent link="palm_link" />
        <child link="finger4_1_link" />
        <limit effort="10" velocity="10" lower="0.0"  upper="1.57" />
    </joint>

    <link name="finger4_2_link">
        <visual>
            <origin xyz="0 0 0" rpy="0 0 1.57" />
            <geometry>
                <mesh filename="file:///home/wai/workspace/ros2_ws/src/robot_nano_hand_teleop/models/robot_nano_hand_finger4_link2.stl" scale="1 1 1"/>
            </geometry>
        </visual>

    </link> 

    <joint name="finger412_joint" type="revolute">
        <origin xyz="0 0 0.0026" rpy="0 0 0" />
        <parent link="finger4_1_link" />
        <child link="finger4_2_link" />
        <limit effort="10" velocity="10" lower="0.0"  upper="1.57" />
    </joint>


    <link name="finger4_3_link">
        <visual>
            <origin xyz="0 0 0" rpy="0 0 1.57" />
            <geometry>
                <mesh filename="file:///home/wai/workspace/ros2_ws/src/robot_nano_hand_teleop/models/robot_nano_hand_finger4_link3.stl" scale="1 1 1"/>
            </geometry>
        </visual>
    </link> 

    <joint name="finger423_joint" type="revolute">
        <origin xyz="-0.003183 0 0.045388" rpy="0 0 0" />
        <parent link="finger4_2_link" />
        <child link="finger4_3_link" />
        <limit effort="10" velocity="10" lower="0.0"  upper="1.57" />
    </joint>

    <link name="finger4_4_link">
        <visual>
            <origin xyz="0 0 0" rpy="0 0 1.57" />
            <geometry>
                <mesh filename="file:///home/wai/workspace/ros2_ws/src/robot_nano_hand_teleop/models/robot_nano_hand_finger4_link4.stl" scale="1 1 1"/>
            </geometry>
        </visual>

    </link> 


    <joint name="finger434_joint" type="revolute">
        <origin xyz="-0.002027 0 0.03436" rpy="0 0 0" />
        <parent link="finger4_3_link"/>
        <child link="finger4_4_link" />
        <limit effort="10" velocity="10" lower="0.0"  upper="1.57" />
    </joint>
   <!--/Finger4--> 


    <!-- Finger5 Thumb-->
    <link name="finger5_1_link">
        <visual>
            <origin xyz="0 0 0" rpy="0 0 1.57" />
            <geometry>
                <mesh filename="file:///home/wai/workspace/ros2_ws/src/robot_nano_hand_teleop/models/robot_nano_hand_finger5_link1.stl" scale="1 1 1"/>
            </geometry>   
        </visual>
    </link> 

    <joint name="palm_finger51_joint" type="revolute">
        <origin xyz="0.032235 0.011296 0.063093" rpy="-0.11638 0.102391 -0.414915" />
        <parent link="palm_link" />
        <child link="finger5_1_link" />
        <limit effort="10" velocity="10" lower="0.0"  upper="1.57" />
    </joint>

    <link name="finger5_2_link">
        <visual>
            <origin xyz="0 0 0" rpy="0 0 1.57" />
            <geometry>
                <mesh filename="file:///home/wai/workspace/ros2_ws/src/robot_nano_hand_teleop/models/robot_nano_hand_finger5_link2.stl" scale="1 1 1"/>
            </geometry>
        </visual>

    </link> 

    <joint name="finger512_joint" type="revolute">
        <origin xyz="0 0.008 -0.0023" rpy="0 0 0" />
        <parent link="finger5_1_link" />
        <child link="finger5_2_link" />
        <limit effort="10" velocity="10" lower="0.0"  upper="1.57" />
    </joint>


    <link name="finger5_3_link">
        <visual>
            <origin xyz="0 0 0" rpy="0 0 1.57" />
            <geometry>
                <mesh filename="file:///home/wai/workspace/ros2_ws/src/robot_nano_hand_teleop/models/robot_nano_hand_finger5_link3.stl" scale="1 1 1"/>
            </geometry>
        </visual>
    </link> 

    <joint name="finger523_joint" type="revolute">
        <origin xyz="0 0.002993 0.043897" rpy="0 0 0" />
        <parent link="finger5_2_link" />
        <child link="finger5_3_link" />
        <limit effort="10" velocity="10" lower="0.0"  upper="1.57" />
    </joint>

    <link name="finger5_4_link">
        <visual>
            <origin xyz="0 0 0" rpy="0 0 1.57" />
            <geometry>
                <mesh filename="file:///home/wai/workspace/ros2_ws/src/robot_nano_hand_teleop/models/robot_nano_hand_finger5_link4.stl" scale="1 1 1"/>
            </geometry>
        </visual>

    </link> 


    <joint name="finger534_joint" type="revolute">
        <origin xyz="0.000012 0.001 0.037986" rpy="0 0 0" />
        <parent link="finger5_3_link"/>
        <child link="finger5_4_link" />
        <limit effort="10" velocity="10" lower="0.0"  upper="1.57" />
    </joint>
   <!--/Finger3--> 

   
</robot>
     

